Workbook
Name _ftn1: 'Gráfico 13'!#REF!
Name _ftn1: 'Gráfico 15'!#REF!
Name _ftn1: 'Gráfico 16'!#REF!
Name _ftn1: 'Gráfico 17'!#REF!
Name _ftn1: 'Gráfico 18'!#REF!
Name _ftn1: 'Gráfico 19'!#REF!
Name _ftn1: 'Gráfico 20'!#REF!
Name _ftn1: 'Gráfico 21'!#REF!
Name _ftn1: 'Gráfico 3'!#REF!
Name _ftn1: 'Gráfico 4'!#REF!
Name _ftn1: 'Gráfico 5'!#REF!
Name _ftn1: 'Gráfico 6'!#REF!
Name _ftn1: 'Gráfico 8'!#REF!
Name _ftn1: 'Gráfico 9'!#REF!
Name _ftn1: 'Ilustración 20'!#REF!
Name _ftn1: 'Ilustración 21'!#REF!
Name _ftn1: 'Ilustración 22'!#REF!
Name _ftn1: 'Tabla 100'!#REF!
Name _ftn1: 'Tabla 101'!#REF!
Name _ftn1: 'Tabla 105'!#REF!
Name _ftn1: 'Tabla 108'!#REF!
Name _ftn1: 'Tabla 110'!#REF!
Name _ftn1: 'Tabla 111'!#REF!
Name _ftn1: 'Tabla 112'!#REF!
Name _ftn1: 'Tabla 113'!#REF!
Name _ftn1: 'Tabla 114'!#REF!
Name _ftn1: 'Tabla 115'!#REF!
Name _ftn1: 'Tabla 116'!#REF!
Name _ftn1: 'Tabla 121'!#REF!
Name _ftn1: 'Tabla 122'!#REF!
Name _ftn1: 'Tabla 123'!#REF!
Name _ftn1: 'Tabla 126'!#REF!
Name _ftn1: 'Tabla 127'!#REF!
Name _ftn1: 'Tabla 131'!#REF!
Name _ftn1: 'Tabla 132'!#REF!
Name _ftn1: 'Tabla 133'!#REF!
Name _ftn1: 'Tabla 134'!#REF!
Name _ftn1: 'Tabla 135'!#REF!
Name _ftn1: 'Tabla 136'!#REF!
Name _ftn1: 'Tabla 137'!#REF!
Name _ftn1: 'Tabla 138'!#REF!
Name _ftn1: 'Tabla 139'!#REF!
Name _ftn1: 'Tabla 144'!#REF!
Name _ftn1: 'Tabla 145'!#REF!
Name _ftn1: 'Tabla 147'!#REF!
Name _ftn1: 'Tabla 148'!#REF!
Name _ftn1: 'Tabla 149'!#REF!
Name _ftn1: 'Tabla 150'!#REF!
Name _ftn1: 'Tabla 151'!#REF!
Name _ftn1: 'Tabla 152'!#REF!
Name _ftn1: 'Tabla 153'!#REF!
Name _ftn1: 'Tabla 154'!#REF!
Name _ftn1: 'Tabla 156'!#REF!
Name _ftn1: 'Tabla 157'!#REF!
Name _ftn1: 'Tabla 159'!#REF!
Name _ftn1: 'Tabla 161'!#REF!
Name _ftn1: 'Tabla 164'!#REF!
Name _ftn1: 'Tabla 165'!#REF!
Name _ftn1: 'Tabla 166'!#REF!
Name _ftn1: 'Tabla 167'!#REF!

Sheet Respaldo
A1: No | B1: Factor | C1: SUBCAPÍTULO/CARACTERÍSTICA | D1: Tabla No | E1: Gráfico | F1: Nombre | G1: Fuente | H1: Responsable Información | I1: Enlace
A2: 1 | B2: CONTEXTO INSTITUCIONAL | C2: Cifras institucionales | D2: 1 | F2: Evolución de la oferta académica de la Sede Bogotá en el quinquenio | G2: DAC | H2: Hector pérez | I2: Sebastián Diaz
A3: 2 | B3: CONTEXTO INSTITUCIONAL | C3: Cifras institucionales | D3: 2 | F3: Distribución de la oferta académica por facultades | G3: DAC | H3: Hector pérez | I3: Sebastián Diaz
A4: 3 | B4: CONTEXTO INSTITUCIONAL | C4: Cifras institucionales | D4: 3 | F4: Programas acreditados en alta calidad en la Sede Bogotá | G4: DAC | H4: Hector pérez | I4: Sebastián Diaz
A5: 4 | B5: CONTEXTO INSTITUCIONAL | C5: Cifras institucionales | D5: 4 | F5: Programas con informe de autoevaluación radicado en CNA | G5: DAC | H5: Hector pérez | I5: Sebastián Diaz
A6: 5 | B6: CONTEXTO INSTITUCIONAL | C6: Cifras institucionales | D6: 5 | F6: Programas con condiciones iniciales aprobadas | G6: DAC | H6: Hector pérez | I6: Sebastián Diaz
A7: 6 | B7: CONTEXTO INSTITUCIONAL | C7: Cifras institucionales | D7: 6 | F7: Matrícula de estudiantes 2019-2 a 2024-1 | G7: Datos y Analítica | H7: Javier Mendieta | I7: Maylor Sabio
A8: 7 | B8: CONTEXTO INSTITUCIONAL | C8: Cifras institucionales | E8: 1 | F8: Profesores por dedicación 2019-2 a 2024-1 | G8: Dirección de Docencia | H8: Lina Giraldo | I8: Ángela Ramírez
A9: 8 | B9: CONTEXTO INSTITUCIONAL | C9: Cifras institucionales | E9: 2 | F9: Profesores por nivel de formación | G9: Dirección de Docencia | H9: Lina Giraldo | I9: Ángela Ramírez
A10: 9 | B10: CONTEXTO INSTITUCIONAL | C10: Cifras institucionales | D10: 7 | F10: Graduados por nivel de formación y modalidad 2019-2 a 2024-1 | G10: Datos y Analítica | H10: Javier Mendieta | I10: Maylor Sabio
A11: 10 | B11: CONTEXTO INSTITUCIONAL | C11: Cifras institucionales | D11: 8 | F11: Grupos de investigación categorizados en Ministerio de Ciencias, Tecnología e Innovación Minciencias | G11: Dir Investigación | H11: Jenny Hernández | I11: David Ricciulli
A12: 11 | B12: CONTEXTO INSTITUCIONAL | C12: Cifras institucionales | D12: 9 | F12: Investigadores categorizados Minciencias | G12: Dir Investigación | H12: Jenny Hernández | I12: David Ricciulli
A13: 12 | B13: CONTEXTO INSTITUCIONAL | C13: Cifras institucionales | D13: 10 | F13: Semilleros por facultad 2019-2- a 2024-1 | G13: Dir Investigación | H13: Jenny Hernández | I13: David Ricciulli
A14: 13 | B14: FACTOR 1. Identidad institucional | C14: Característica 3. Formación integral y construcción de identidad | D14: 23 | F14: Resultados de las acciones de formación integral | G14: DAC | H14: Hector pérez | I14: Carlos Rincón
A15: 14 | B15: FACTOR 1. Identidad institucional | C15: Característica 6. Rendición de cuentas | D15: 29 | F15: Visualizaciones del informe de sostenibilidad anual | G15: Gerencia de Planeación y Gestión | H15: Liliana Bernal | I15: Camilo Chacón
A16: 15 | B16: FACTOR 3. Desarrollo, gestión y sostenibilidad institucional | C16: Característica 7. Administración y Gestión | D16: 32 | F16: Personal administrativo beneficiado con políticas de estímulos 2019-2 a 2024-1 | G16: Gerencia Talento HUmano | H16: Andrea Carmona | I16: Francy Lineth Castrillón
A17: 16 | B17: FACTOR 3. Desarrollo, gestión y sostenibilidad institucional | C17: Característica 7. Administración y Gestión | D17: 33 | F17: Participación de administrativos en formación | G17: Gerencia Talento HUmano | H17: Andrea Carmona | I17: Francy Lineth Castrillón
A18: 17 | B18: FACTOR 3. Desarrollo, gestión y sostenibilidad institucional | C18: Característica 7. Administración y Gestión | D18: 34 | F18: Ascensos en la planta administrativa | G18: Gerencia Talento HUmano | H18: Mónica Avendaño | I18: Mónica Avendaño
A19: 18 | B19: FACTOR 3. Desarrollo, gestión y sostenibilidad institucional | C19: Característica 8. Procesos de COmunicación | E19: Ilustración 20 | F19: Frecuencia de uso de medios de comunicación para informarse | G19: Gerencia de Mercadeo / Estudio Brand equity Kanta | H19: Nestor Ivan Moreno | I19: Laura Barrera
A20: 19 | B20: FACTOR 3. Desarrollo, gestión y sostenibilidad institucional | C20: Característica 8. Procesos de COmunicación | E20: Ilustración 21 | F20: Medios destacados para el Poli | G20: Gerencia de Mercadeo / Estudio Brand equity Kanta | H20: Nestor Ivan Moreno | I20: Laura Barrera
A21: 20 | B21: FACTOR 3. Desarrollo, gestión y sostenibilidad institucional | C21: Característica 8. Procesos de COmunicación | E21: Ilustración 22 | F21: Alcance de personas en Redes sociales cuentas del Poli | G21: Dirección de marca | H21: Nestor Ivan Moreno | I21: Laura Barrera
A22: 21 | B22: FACTOR 3. Desarrollo, gestión y sostenibilidad institucional | C22: Característica 8. Procesos de COmunicación | D22: 36 | F22: Leads obtenidos año a año por canal en el Poli | G22: Dirección de marca | H22: Nestor Ivan Moreno | I22: Laura Barrera
A23: 22 | B23: FACTOR 3. Desarrollo, gestión y sostenibilidad institucional | C23: Característica 10. Recursos de apoyo académico | D23: 39 | F23: Tipología de recursos documentales en la Biblioteca | G23: Dirección de Bibliotecas | H23: Carmen Romero | I23: Elizabeth Rodríguez Mora
A24: 23 | B24: FACTOR 3. Desarrollo, gestión y sostenibilidad institucional | C24: Característica 10. Recursos de apoyo académico | D24: 40 | F24: Libros por área de conocimiento | G24: Dirección de Bibliotecas | H24: Carmen Romero | I24: Elizabeth Rodríguez Mora
A25: 24 | B25: FACTOR 3. Desarrollo, gestión y sostenibilidad institucional | C25: Característica 10. Recursos de apoyo académico | D25: 41 | F25: Revistas por área de conocimiento | G25: Dirección de Bibliotecas | H25: Carmen Romero | I25: Elizabeth Rodríguez Mora
A26: 25 | B26: FACTOR 3. Desarrollo, gestión y sostenibilidad institucional | C26: Característica 10. Recursos de apoyo académico | D26: 42 | F26: Recursos bibliográficos 2019-2 a 2024-1 | G26: Dirección de Bibliotecas | H26: Carmen Romero | I26: Elizabeth Rodríguez Mora
A27: 26 | B27: FACTOR 3. Desarrollo, gestión y sostenibilidad institucional | C27: Característica 10. Recursos de apoyo académico | D27: 43 | F27: Uso de los Recursos Bibliográficos 2019-2 a 2024-1 | G27: Dirección de Bibliotecas | H27: Carmen Romero | I27: Elizabeth Rodríguez Mora
A28: 27 | B28: FACTOR 3. Desarrollo, gestión y sostenibilidad institucional | C28: Característica 10. Recursos de apoyo académico | D28: 44 | F28: Divulgación periódica revistas | G28: Editorial | H28: Eduardo Norman Acevedo | I28: Guillermo Alberto González
A29: 28 | B29: FACTOR 3. Desarrollo, gestión y sostenibilidad institucional | C29: Característica 10. Recursos de apoyo académico | E29: 3 | F29: Estado de los ambientes inmersivos | G29: Secretaría Académica y de Extensión | H29: Luis Martín Trujillo | I29: Luis Martín Trujillo
A30: 29 | B30: FACTOR 3. Desarrollo, gestión y sostenibilidad institucional | C30: Característica 10. Recursos de apoyo académico | D30: 45 | F30: Ambientes inmersivos registrados a nombre del Politécnico Grancolombiano | G30: Secretaría Académica y de Extensión | H30: Luis Martín Trujillo | I30: Luis Martín Trujillo
A31: 30 | B31: FACTOR 3. Desarrollo, gestión y sostenibilidad institucional | C31: Característica 10. Recursos de apoyo académico | D31: 46 | F31: Histórico de la salida a los estudiantes de los diferentes ambientes | G31: Secretaría Académica y de Extensión | H31: Luis Martín Trujillo | I31: Luis Martín Trujillo
A32: 31 | B32: FACTOR 3. Desarrollo, gestión y sostenibilidad institucional | C32: Característica 10. Recursos de apoyo académico | D32: 47 | F32: Uso de los ambientes inmersivos por los estudiantes Poli | G32: Secretaría Académica y de Extensión | H32: Luis Martín Trujillo | I32: Luis Martín Trujillo
A33: 32 | B33: FACTOR 3. Desarrollo, gestión y sostenibilidad institucional | C33: Característica 10. Recursos de apoyo académico | D33: 48 | F33: Distribución de los MI-Books por facultades | G33: Secretaría Académica y de Extensión | H33: Luis Martín Trujillo | I33: Luis Martín Trujillo
A34: 33 | B34: FACTOR 3. Desarrollo, gestión y sostenibilidad institucional | C34: Característica 10. Recursos de apoyo académico | E34: 4 | F34: Medición uso recorridos | G34: Secretaría Académica y de Extensión | H34: Luis Martín Trujillo | I34: Luis Martín Trujillo
A35: 34 | B35: FACTOR 3. Desarrollo, gestión y sostenibilidad institucional | C35: Característica 10. Recursos de apoyo académico | D35: 49 | F35: Visitas MI-Books por país | G35: Secretaría Académica y de Extensión | H35: Luis Martín Trujillo | I35: Luis Martín Trujillo
A36: 35 | B36: FACTOR 3. Desarrollo, gestión y sostenibilidad institucional | C36: Característica 10. Recursos de apoyo académico | D36: 53 | F36: Talleres y laboratorios de la Institución | G36: Dirección de Infraestructura | H36: Raul Ricardo Cortes Rincón | I36: Edith marthza Nino
A37: 36 | B37: FACTOR 3. Desarrollo, gestión y sostenibilidad institucional | C37: Característica 10. Recursos de apoyo académico | E37: 5 | F37: Sitios de práctica | G37: Dir Graduados y Proyección Empresarial | H37: Luis Miguel Corredor | I37: Luis Miguel Corredor
A38: 37 | B38: FACTOR 3. Desarrollo, gestión y sostenibilidad institucional | C38: Característica 11. Infraestructura Física y Tecnológica | D38: 55 | F38: Infraestructura física del Poli | G38: Dirección de Infraestructura | H38: Raul Ricardo Cortes Rincón | I38: Edith marthza Nino
A39: 38 | B39: FACTOR 3. Desarrollo, gestión y sostenibilidad institucional | C39: Característica 11. Infraestructura Física y Tecnológica | D39: 57 | F39: Infraestructura física 2019-2 a 2024-1 | G39: Dirección de Infraestructura | H39: Raul Ricardo Cortes Rincón | I39: Edith marthza Nino
A40: 39 | B40: FACTOR 3. Desarrollo, gestión y sostenibilidad institucional | C40: Característica 11. Infraestructura Física y Tecnológica | D40: 58 | F40: Infraestructura Tecnológica 2019-2 a 2024-1 | G40: Dirección de Infraestructura | H40: Uriel Mejia Terán | I40: Iván Diaz / Diana García
...

Sheet Índice Tablas
A1: Factor | B1: SUBCAPÍTULO/CARACTERÍSTICA | C1: Orden | D1: Tabla No | E1: Gráfico | F1: Nombre | G1: Fuente | H1: Responsable Información | I1: Enlace | J1: Observaciones | BX1: Orden
A2: CONTEXTO INSTITUCIONAL | B2: Cifras institucionales | C2: 1 | D2: 1 | F2: Evolución de la oferta académica de la Sede Bogotá en el quinquenio | G2: DAC | H2: Hector pérez | I2: Sebastián Diaz | BX2: 1
A3: CONTEXTO INSTITUCIONAL | B3: Cifras institucionales | C3: 2 | D3: 2 | F3: Distribución de la oferta académica por facultades | G3: DAC | H3: Hector pérez | I3: Sebastián Diaz | BX3: 2
A4: CONTEXTO INSTITUCIONAL | B4: Cifras institucionales | C4: 3 | D4: 3 | F4: Programas acreditados en alta calidad en la Sede Bogotá | G4: DAC | H4: Hector pérez | I4: Sebastián Diaz | BX4: 3
A5: CONTEXTO INSTITUCIONAL | B5: Cifras institucionales | C5: 4 | D5: 4 | F5: Programas con informe de autoevaluación radicado en CNA | G5: DAC | H5: Hector pérez | I5: Sebastián Diaz | BX5: 4
A6: CONTEXTO INSTITUCIONAL | B6: Cifras institucionales | C6: 5 | D6: 5 | F6: Programas con condiciones iniciales aprobadas | G6: DAC | H6: Hector pérez | I6: Sebastián Diaz | BX6: 5
A7: CONTEXTO INSTITUCIONAL | B7: Cifras institucionales | C7: 6 | D7: 6 | F7: Matrícula de estudiantes 2019-2 a 2025-1 | G7: Datos y Analítica | H7: Javier Mendieta | I7: Maylor Sabio | BX7: 6
A8: CONTEXTO INSTITUCIONAL | B8: Cifras institucionales | C8: 7 | E8: 1 | F8: Profesores por dedicación 2019-2 a 2025-1 | G8: Dirección de Docencia | H8: Lina Giraldo | I8: Ángela Ramírez | BX8: 7
A9: CONTEXTO INSTITUCIONAL | B9: Cifras institucionales | C9: 8 | E9: 2 | F9: Profesores por nivel de formación | G9: Dirección de Docencia | H9: Lina Giraldo | I9: Ángela Ramírez | BX9: 8
A10: CONTEXTO INSTITUCIONAL | B10: Cifras institucionales | C10: 9 | D10: 7 | F10: Graduados por nivel de formación y modalidad 2019-2 a 2025-1 | G10: Datos y Analítica | H10: Javier Mendieta | I10: Maylor Sabio | BX10: 9
A11: CONTEXTO INSTITUCIONAL | B11: Cifras institucionales | C11: 10 | D11: 8 | F11: Grupos de investigación categorizados en Ministerio de Ciencias, Tecnología e Innovación Minciencias | G11: Dir Investigación | H11: Jenny Hernández | I11: David Ricciulli | J11: Nota: Se actualizan con los últimos resultados Convocatoria 957 | BX11: 10
A12: CONTEXTO INSTITUCIONAL | B12: Cifras institucionales | C12: 11 | D12: 9 | F12: Investigadores categorizados Minciencias | G12: Dir Investigación | H12: Jenny Hernández | I12: David Ricciulli | J12: Nota: Se actualizan con los últimos resultados Convocatoria 957 | BX12: 11
A13: CONTEXTO INSTITUCIONAL | B13: Cifras institucionales | C13: 12 | D13: 10 | F13: Semilleros por facultad 2019-2- a 2025-1 | G13: Dir Investigación | H13: Jenny Hernández | I13: David Ricciulli | BX13: 12
A14: FACTOR 1. Identidad institucional | B14: Característica 3. Formación integral y construcción de identidad | C14: 13 | D14: 23 | F14: Resultados de las acciones de formación integral | G14: DAC | H14: Hector pérez | I14: Carlos Rincón | BX14: 13
A15: FACTOR 1. Identidad institucional | B15: Característica 6. Rendición de cuentas | C15: 14 | D15: 29 | F15: Visualizaciones del informe de sostenibilidad anual | G15: Gerencia de Planeación y Gestión | H15: Liliana Bernal | I15: Camilo Chacón | BX15: 14
A16: FACTOR 3. Desarrollo, gestión y sostenibilidad institucional | B16: Característica 7. Administración y Gestión | C16: 15 | D16: 32 | F16: Personal administrativo beneficiado con políticas de estímulos 2019-2 a 2025-1 | G16: Gerencia Talento HUmano | H16: Andrea Carmona | I16: Francy Lineth Castrillón | BX16: 15
A17: FACTOR 3. Desarrollo, gestión y sostenibilidad institucional | B17: Característica 7. Administración y Gestión | C17: 16 | D17: 33 | F17: Participación de administrativos en formación | G17: Gerencia Talento HUmano | H17: Andrea Carmona | I17: Francy Lineth Castrillón | BX17: 16
A18: FACTOR 3. Desarrollo, gestión y sostenibilidad institucional | B18: Característica 7. Administración y Gestión | C18: 17 | D18: 34 | F18: Ascensos en la planta administrativa | G18: Gerencia Talento HUmano | H18: Mónica Avendaño | I18: Mónica Avendaño | BX18: 17
A19: FACTOR 3. Desarrollo, gestión y sostenibilidad institucional | B19: Característica 8. Procesos de COmunicación | C19: 18 | E19: Ilustración 20 | F19: Frecuencia de uso de medios de comunicación para informarse | G19: Gerencia de Mercadeo / Estudio Brand equity Kanta | H19: Nestor Ivan Moreno | I19: Laura Barrera | BX19: 18
A20: FACTOR 3. Desarrollo, gestión y sostenibilidad institucional | B20: Característica 8. Procesos de COmunicación | C20: 19 | E20: Ilustración 21 | F20: Medios destacados para el Poli | G20: Gerencia de Mercadeo / Estudio Brand equity | H20: Nestor Ivan Moreno | I20: Laura Barrera | BX20: 19
A21: FACTOR 3. Desarrollo, gestión y sostenibilidad institucional | B21: Característica 8. Procesos de COmunicación | C21: 20 | E21: Ilustración 22 | F21: Alcance de personas en Redes sociales cuentas del Poli | G21: Dirección de marca | H21: Nestor Ivan Moreno | I21: Laura Barrera | BX21: 20
A22: FACTOR 3. Desarrollo, gestión y sostenibilidad institucional | B22: Característica 8. Procesos de COmunicación | C22: 21 | D22: 36 | F22: Leads obtenidos año a año por canal en el Poli | G22: Dirección de marca | H22: Nestor Ivan Moreno | I22: Natalia Rincón | BX22: 21
A23: FACTOR 3. Desarrollo, gestión y sostenibilidad institucional | B23: Característica 10. Recursos de apoyo académico | C23: 22 | D23: 39 | F23: Tipología de recursos documentales en la Biblioteca 2025-1 | G23: Dirección de Bibliotecas | H23: Carmen Romero | I23: Elizabeth Rodríguez Mora | BX23: 22
A24: FACTOR 3. Desarrollo, gestión y sostenibilidad institucional | B24: Característica 10. Recursos de apoyo académico | C24: 23 | D24: 40 | F24: Libros por área de conocimiento | G24: Dirección de Bibliotecas | H24: Carmen Romero | I24: Elizabeth Rodríguez Mora | BX24: 23
A25: FACTOR 3. Desarrollo, gestión y sostenibilidad institucional | B25: Característica 10. Recursos de apoyo académico | C25: 24 | D25: 41 | F25: Revistas por área de conocimiento | G25: Dirección de Bibliotecas | H25: Carmen Romero | I25: Elizabeth Rodríguez Mora | BX25: 24
A26: FACTOR 3. Desarrollo, gestión y sostenibilidad institucional | B26: Característica 10. Recursos de apoyo académico | C26: 25 | D26: 42 | F26: Recursos bibliográficos 2019-2 a 2025-1 | G26: Dirección de Bibliotecas | H26: Carmen Romero | I26: Elizabeth Rodríguez Mora | BX26: 25
A27: FACTOR 3. Desarrollo, gestión y sostenibilidad institucional | B27: Característica 10. Recursos de apoyo académico | C27: 26 | D27: 43 | F27: Uso de los Recursos Bibliográficos 2019-2 a 2025-1 | G27: Dirección de Bibliotecas | H27: Carmen Romero | I27: Elizabeth Rodríguez Mora | BX27: 26
A28: FACTOR 3. Desarrollo, gestión y sostenibilidad institucional | B28: Característica 10. Recursos de apoyo académico | C28: 27 | D28: 44 | F28: Divulgación periódica revistas | G28: Editorial | H28: Guillermo Alberto González | I28: Guillermo Alberto González | BX28: 27
A29: FACTOR 3. Desarrollo, gestión y sostenibilidad institucional | B29: Característica 10. Recursos de apoyo académico | C29: 28 | E29: 3 | F29: Estado de los ambientes inmersivos | G29: Secretaría Académica y de Extensión | H29: Luis Martín Trujillo | I29: Luis Martín Trujillo | BX29: 28
A30: FACTOR 3. Desarrollo, gestión y sostenibilidad institucional | B30: Característica 10. Recursos de apoyo académico | C30: 29 | D30: 45 | F30: Ambientes inmersivos registrados a nombre del Politécnico Grancolombiano | G30: Secretaría Académica y de Extensión | H30: Luis Martín Trujillo | I30: Luis Martín Trujillo | BX30: 29
A31: FACTOR 3. Desarrollo, gestión y sostenibilidad institucional | B31: Característica 10. Recursos de apoyo académico | C31: 30 | D31: 46 | F31: Histórico de la salida a los estudiantes de los diferentes ambientes | G31: Secretaría Académica y de Extensión | H31: Luis Martín Trujillo | I31: Luis Martín Trujillo | BX31: 30
A32: FACTOR 3. Desarrollo, gestión y sostenibilidad institucional | B32: Característica 10. Recursos de apoyo académico | C32: 31 | D32: 47 | F32: Uso de los ambientes inmersivos por los estudiantes Poli | G32: Secretaría Académica y de Extensión | H32: Luis Martín Trujillo | I32: Luis Martín Trujillo | BX32: 31
A33: FACTOR 3. Desarrollo, gestión y sostenibilidad institucional | B33: Característica 10. Recursos de apoyo académico | C33: 32 | D33: 48 | F33: Distribución de los MI-Books por facultades | G33: Secretaría Académica y de Extensión | H33: Luis Martín Trujillo | I33: Luis Martín Trujillo | BX33: 32
A34: FACTOR 3. Desarrollo, gestión y sostenibilidad institucional | B34: Característica 10. Recursos de apoyo académico | C34: 33 | E34: 4 | F34: Medición uso recorridos | G34: Secretaría Académica y de Extensión | H34: Luis Martín Trujillo | I34: Luis Martín Trujillo | BX34: 33
A35: FACTOR 3. Desarrollo, gestión y sostenibilidad institucional | B35: Característica 10. Recursos de apoyo académico | C35: 34 | D35: 49 | F35: Visitas MI-Books por país | G35: Secretaría Académica y de Extensión | H35: Luis Martín Trujillo | I35: Luis Martín Trujillo | BX35: 34
A36: FACTOR 3. Desarrollo, gestión y sostenibilidad institucional | B36: Característica 10. Recursos de apoyo académico | C36: 35 | D36: 53 | F36: Talleres y laboratorios de la Institución | G36: Dirección de Infraestructura | H36: Raul Ricardo Cortes Rincón | I36: Edith marthza Nino | BX36: 35
A37: FACTOR 3. Desarrollo, gestión y sostenibilidad institucional | B37: Característica 10. Recursos de apoyo académico | C37: 36 | E37: 5 | F37: Sitios de práctica | G37: Dir Graduados y Proyección Empresarial | H37: Luis Miguel Corredor | I37: Luis Miguel Corredor | BX37: 36
A38: FACTOR 3. Desarrollo, gestión y sostenibilidad institucional | B38: Característica 11. Infraestructura Física y Tecnológica | C38: 37 | D38: 55 | F38: Infraestructura física del Poli | G38: Dirección de Infraestructura | H38: Raul Ricardo Cortes Rincón | I38: Edith marthza Nino | BX38: 37
A39: FACTOR 3. Desarrollo, gestión y sostenibilidad institucional | B39: Característica 11. Infraestructura Física y Tecnológica | C39: 38 | D39: 57 | F39: Infraestructura física 2019-2 a 2025-1 | G39: Dirección de Infraestructura | H39: Raul Ricardo Cortes Rincón | I39: Edith marthza Nino | BX39: 38
A40: FACTOR 3. Desarrollo, gestión y sostenibilidad institucional | B40: Característica 11. Infraestructura Física y Tecnológica | C40: 39 | D40: 58 | F40: Infraestructura Tecnológica 2019-2 a 2025-1 | G40: Dirección de Infraestructura | H40: Uriel Mejia Terán | I40: Iván Diaz / Diana García | BX40: 39
...

Sheet Tabla 1
A1: Tabla NO | B1: 1
A2: Nombre | B2: Evolución de la oferta académica de la Sede Bogotá en el quinquenio
A3: MODALIDAD | B3: NIVEL DE FORMACIÓN | C3: 2019 | D3: 2020 | E3: 2021 | F3: 2022 | G3: 2023 | H3: 2024-1 | I3: 2024-2 | J3: 2025-1 | K3: 2025-2 | L3: 2026-1
A4: PRESENCIAL | B4: TECNOLÓGICOS | C4: 4 | D4: 4 | E4: 3 | F4: 3 | G4: 2 | H4: 2 | I4: 2 | J4: 2 | K4: 2 | L4: 2
B5: PROFESIONALES UNIVERSITARIOS | C5: 20 | D5: 20 | E5: 19 | F5: 21 | G5: 20 | H5: 20 | I5: 20 | J5: 20 | K5: 19 | L5: 19
B6: ESPECIALIZACIONES UNIVERSITARIAS | C6: 10 | D6: 11 | E6: 12 | F6: 12 | G6: 11 | H6: 11 | I6: 11 | J6: 11 | K6: 11 | L6: 10
B7: MAESTRÍAS | C7: 5 | D7: 5 | E7: 5 | F7: 5 | G7: 5 | H7: 5 | I7: 3 | J7: 3 | K7: 2 | L7: 2
A8: VIRTUAL | B8: TÉCNICOS PROFESIONALES | C8: 2 | D8: 2 | E8: 2 | F8: 2 | G8: 2 | H8: 2 | I8: 2 | J8: 2 | K8: 2 | L8: 3
B9: TECNOLÓGICOS | C9: 7 | D9: 8 | E9: 8 | F9: 8 | G9: 7 | H9: 7 | I9: 7 | J9: 7 | K9: 7 | L9: 7
B10: PROFESIONALES UNIVERSITARIOS | C10: 10 | D10: 11 | E10: 15 | F10: 17 | G10: 17 | H10: 19 | I10: 19 | J10: 22 | K10: 22 | L10: 25
B11: ESPECIALIZACIONES TECNOLÓGICAS | C11: 1 | D11: 0 | E11: 0 | F11: 0 | G11: 0 | H11: 0 | I11: 0 | J11: 0 | K11: 0 | L11: 0
B12: ESPECIALIZACIONES UNIVERSITARIAS | C12: 10 | D12: 10 | E12: 11 | F12: 10 | G12: 9 | H12: 9 | I12: 9 | J12: 10 | K12: 10 | L12: 11
B13: MAESTRÍAS | C13: 0 | D13: 0 | E13: 3 | F13: 4 | G13: 4 | H13: 7 | I13: 7 | J13: 14 | K13: 14 | L13: 17
A14: TOTAL | C14: 69 | D14: 71 | E14: 78 | F14: 82 | G14: 77 | H14: 82 | I14: =SUM(I4:I13) -> 80 | J14: =SUM(J4:J13) -> 91 | K14: =SUM(K4:K13) -> 89 | L14: 96

Sheet Tabla 2
A1: Tabla NO | B1: 2
A2: Nombre | B2: Distribución de la oferta académica por facultades
A4: FACULTAD | B4: PREGRADO | D4: POSGRADO | F4: TOTAL
B5: PRESENCIAL | C5: VIRTUAL | D5: PRESENCIAL | E5: VIRTUAL
A6: FACULTAD DE INGENIERÍA, DISEÑO E INNOVACIÓN | B6: 11 | C6: 5 | D6: 3 | E6: 7 | F6: =SUM(B6:E6) -> 26
A7: FACULTAD DE NEGOCIOS, GESTIÓN Y SOSTENIBILIDAD | B7: 6 | C7: 12 | D7: 4 | E7: 9 | F7: =SUM(B7:E7) -> 31
A8: FACULTAD DE SOCIEDAD, CULTURA Y CREATIVIDAD | B8: 5 | C8: 14 | D8: 7 | E8: 8 | F8: =SUM(B8:E8) -> 34
A9: TOTAL | B9: =SUM(B6:B8) -> 22 | C9: =SUM(C6:C8) -> 31 | D9: =SUM(D6:D8) -> 14 | E9: =SUM(E6:E8) -> 24 | F9: =SUM(F6:F8) -> 91
A12: 2026-1
A13: FACULTAD | B13: PREGRADO | D13: POSGRADO | F13: TOTAL
B14: PRESENCIAL | C14: VIRTUAL | D14: PRESENCIAL | E14: VIRTUAL
A15: FACULTAD DE INGENIERÍA, DISEÑO E INNOVACIÓN | B15: 10 | C15: 6 | D15: 1 | E15: 9 | F15: =SUM(B15:E15) -> 26
A16: FACULTAD DE NEGOCIOS, GESTIÓN Y SOSTENIBILIDAD | B16: 6 | C16: 13 | D16: 4 | E16: 9 | F16: =SUM(B16:E16) -> 32
A17: FACULTAD DE SOCIEDAD, CULTURA Y CREATIVIDAD | B17: 5 | C17: 16 | D17: 7 | E17: 10 | F17: =SUM(B17:E17) -> 38
A18: TOTAL | B18: =SUM(B15:B17) -> 21 | C18: =SUM(C15:C17) -> 35 | D18: =SUM(D15:D17) -> 12 | E18: =SUM(E15:E17) -> 28 | F18: =SUM(F15:F17) -> 96

Sheet Tabla 3
A1: Tabla NO | B1: 3
A2: Nombre | B2: Programas acreditados en alta calidad en la Sede Bogotá
A5: Nombre | B5: Programas acreditados en alta calidad en la Sede Bogotá 2025-1
A7: SNIES | B7: MODALIDAD | C7: SEDE | D7: FACULTAD | E7: ESCUELA | F7: PROGRAMA | G7: VIGENCIA
A8: 54534 | B8: PRESENCIAL | C8: BOGOTÁ | D8: FIDI | E8: ESCUELA DE DISEÑO | F8: DISEÑO GRÁFICO | G8: 6
A9: 53835 | B9: PRESENCIAL | C9: BOGOTÁ | D9: FIDI | E9: ESCUELA DE TECNOLOGÍA, INFORMACIÓN Y COMUNICACIÓN | F9: INGENIERÍA EN TELECOMUNICACIONES | G9: 6
A10: 10561 | B10: PRESENCIAL | C10: BOGOTÁ | D10: FIDI | E10: ESCUELA DE OPTIMIZACIÓN, INFRAESTRUCTURA Y AUTOMATIZACIÓN | F10: INGENIERÍA INDUSTRIAL | G10: 4
A11: 1895 | B11: PRESENCIAL | C11: BOGOTÁ | D11: FIDI | E11: ESCUELA DE TECNOLOGÍA, INFORMACIÓN Y COMUNICACIÓN | F11: INGENIERÍA DE SISTEMAS | G11: 4
A12: 53237 | B12: PRESENCIAL | C12: BOGOTÁ | D12: FNGS | E12: ESCUELA DE NEGOCIOS Y DESARROLLO INTERNACIONAL | F12: TECNOLOGÍA EN GESTIÓN DE SERVICIOS PARA AEROLÍNEAS | G12: 6
A13: 53178 | B13: VIRTUAL | C13: NACIONAL | D13: FNGS | E13: ESCUELA DE ADMINISTRACIÓN Y COMPETITIVIDAD | F13: TECNOLOGÍA EN GESTIÓN FINANCIERA | G13: 4
A14: 7470 | B14: PRESENCIAL | C14: BOGOTÁ | D14: FNGS | E14: ESCUELA DE NEGOCIOS Y DESARROLLO INTERNACIONAL | F14: NEGOCIOS INTERNACIONALES | G14: 4
A15: 101382 | B15: PRESENCIAL | C15: BOGOTÁ | D15: FNGS | E15: ESCUELA DE ADMINISTRACIÓN Y COMPETITIVIDAD | F15: ADMINISTRACIÓN DE EMPRESAS | G15: 6
A16: 1892 | B16: PRESENCIAL | C16: BOGOTÁ | D16: FSCC | E16: ESCUELA DE MARKETING Y BRANDING | F16: MERCADEO Y PUBLICIDAD | G16: 6
A17: 6699 | B17: PRESENCIAL | C17: BOGOTÁ | D17: FSCC | E17: ESCUELA DE COMUNICACIÓN, ARTES VISUALES Y DIGITALES | F17: PROFESIONAL EN MEDIOS AUDIOVISUALES | G17: 6
A18: 101647 | B18: VIRTUAL | C18: NACIONAL | D18: FSCC | E18: ESCUELA DE DERECHO Y GOBIERNO | F18: TECNICA PROFESIONAL JUDICIAL | G18: 6
A20: Nombre | B20: Programas acreditados en alta calidad en la Sede Bogotá - Nacional 2026-1
A21: SNIES | B21: MODALIDAD | C21: SEDE | D21: FACULTAD | E21: ESCUELA | F21: PROGRAMA | G21: VIGENCIA
A22: 54534 | B22: PRESENCIAL | C22: BOGOTÁ | D22: FIDI | E22: ESCUELA DE DISEÑO | F22: DISEÑO GRÁFICO | G22: 6
A23: 101525 | B23: PRESENCIAL | C23: BOGOTÁ | D23: FIDI | E23: ESCUELA DE DISEÑO | F23: DISEÑO INDUSTRIAL | G23: 6
A24: 53835 | B24: PRESENCIAL | C24: BOGOTÁ | D24: FIDI | E24: ESCUELA DE TECNOLOGÍA, INFORMACIÓN Y COMUNICACIÓN | F24: INGENIERÍA EN TELECOMUNICACIONES | G24: 6
A25: 10561 | B25: PRESENCIAL | C25: BOGOTÁ | D25: FIDI | E25: ESCUELA DE OPTIMIZACIÓN, INFRAESTRUCTURA Y AUTOMATIZACIÓN | F25: INGENIERÍA INDUSTRIAL | G25: 4*
A26: 1895 | B26: PRESENCIAL | C26: BOGOTÁ | D26: FIDI | E26: ESCUELA DE TECNOLOGÍA, INFORMACIÓN Y COMUNICACIÓN | F26: INGENIERÍA DE SISTEMAS | G26: 4
A27: 53237 | B27: PRESENCIAL | C27: BOGOTÁ | D27: FNGS | E27: ESCUELA DE NEGOCIOS Y DESARROLLO INTERNACIONAL | F27: TECNOLOGÍA EN GESTIÓN DE SERVICIOS PARA AEROLÍNEAS | G27: 6
A28: 53178 | B28: VIRTUAL | C28: NACIONAL | D28: FNGS | E28: ESCUELA DE ADMINISTRACIÓN Y COMPETITIVIDAD | F28: TECNOLOGÍA EN GESTIÓN FINANCIERA | G28: 4
A29: 7470 | B29: PRESENCIAL | C29: BOGOTÁ | D29: FNGS | E29: ESCUELA DE NEGOCIOS Y DESARROLLO INTERNACIONAL | F29: NEGOCIOS INTERNACIONALES | G29: 4
A30: 101382 | B30: PRESENCIAL | C30: BOGOTÁ | D30: FNGS | E30: ESCUELA DE ADMINISTRACIÓN Y COMPETITIVIDAD | F30: ADMINISTRACIÓN DE EMPRESAS | G30: 6
A31: 1892 | B31: PRESENCIAL | C31: BOGOTÁ | D31: FSCC | E31: ESCUELA DE MARKETING Y BRANDING | F31: MERCADEO Y PUBLICIDAD | G31: 6
A32: 6699 | B32: PRESENCIAL | C32: BOGOTÁ | D32: FSCC | E32: ESCUELA DE COMUNICACIÓN, ARTES VISUALES Y DIGITALES | F32: MEDIOS AUDIOVISUALES | G32: 6
A33: 3638 | B33: PRESENCIAL | C33: BOGOTÁ | D33: FSCC | E33: ESCUELA DE COMUNICACIÓN, ARTES VISUALES Y DIGITALES | F33: COMUNICACIÓN SOCIAL - PERIODISMO | G33: 6
A34: 91360 | B34: PRESENCIAL | C34: BOGOTÁ | D34: FSCC | E34: ESCUELA DE MARKETING Y BRANDING | F34: MAESTRÍA EN GERENCIA ESTRATÉGICA DE MERCADEO | G34: 6
A35: 103799 | B35: VIRTUAL | C35: NACIONAL | D35: FSCC | E35: ESCUELA DE PSICOLOGÍA, TALENTO HUMANO Y SOCIEDAD | F35: PROFESIONAL EN GESTIÓN DE LA SEGURIDAD Y LA SALUD LABORAL | G35: 6
A36: 101647 | B36: VIRTUAL | C36: NACIONAL | D36: FSCC | E36: ESCUELA DE DERECHO Y GOBIERNO | F36: TÉCNICA PROFESIONAL JUDICIAL | G36: 6

Sheet Tabla 4
A1: Tabla NO | B1: 4
A2: Nombre | B2: Programas con informe de autoevaluación radicado en CNA
A4: SNIES | B4: MODALIDAD | C4: SEDE | D4: FACULTAD | E4: ESCUELA | F4: PROGRAMA
A5: 101525 | B5: PRESENCIAL | C5: BOGOTÁ | D5: FIDI | E5: ESCUELA DE DISEÑO | F5: DISEÑO INDUSTRIAL
A6: 91360 | B6: PRESENCIAL | C6: BOGOTÁ | D6: FSCC | E6: ESCUELA DE MARKETING Y BRANDING | F6: MAESTRÍA EN GERENCIA ESTRATÉGICA DE MERCADEO
A7: 3638 | B7: PRESENCIAL | C7: BOGOTÁ | D7: FSCC | E7: ESCUELA DE COMUNICACIÓN, ARTES VISUALES Y DIGITALES | F7: COMUNICACIÓN SOCIAL – PERIODISMO
A8: 103799 | B8: VIRTUAL | C8: NACIONAL | D8: FSCC | E8: ESCUELA DE PSICOLOGÍA, TALENTO HUMANO Y SOCIEDAD | F8: PROFESIONAL EN GESTIÓN DE LA SEGURIDAD Y LA SALUD LABORAL
A9: 101647 | B9: VIRTUAL | C9: NACIONAL | D9: FSCC | E9: ESCUELA DE DERECHO Y GOBIERNO | F9: TÉCNICA PROFESIONAL JUDICIAL
A12: Nombre | B12: Programas con informe de autoevaluación radicado en CNA 2026-1
A14: SNIES | B14: MODALIDAD | C14: SEDE | D14: FACULTAD | E14: ESCUELA | F14: PROGRAMA
A15: 102473 | B15: PRESENCIAL | C15: MEDELLÍN | D15: FIDI | E15: ESCUELA DE OPTIMIZACIÓN, INFRAESTRUCTURA Y AUTOMATIZACIÓN | F15: INGENIERÍA INDUSTRIAL
A16: 53178 | B16: VIRTUAL | C16: NACIONAL | D16: FNGS | E16: ESCUELA DE ADMINISTRACIÓN Y COMPETITIVIDAD | F16: TECNOLOGÍA EN GESTIÓN FINANCIERA
A17: 7470 | B17: PRESENCIAL | C17: BOGOTÁ | D17: FNGS | E17: ESCUELA DE NEGOCIOS Y DESARROLLO INTERNACIONAL | F17: NEGOCIOS INTERNACIONALES
A18: 103752 | B18: PRESENCIAL | C18: MEDELLÍN | D18: FSCC | E18: ESCUELA DE PSICOLOGÍA, TALENTO HUMANO Y SOCIEDAD | F18: PSICOLOGÍA

Sheet Hoja1
A1: SNIES | B1: MODALIDAD | C1: SEDE | D1: FACULTAD | E1: ESCUELA | F1: PROGRAMA
A2: 103752 | B2: PRESENCIAL | C2: MEDELLÍN | D2: FSCC | E2: ESCUELA DE PSICOLOGÍA, TALENTO HUMANO Y SOCIEDAD | F2: PSICOLOGÍA

Sheet Gráfico 1
A1: Gráfico No | B1: 1
A2: Nombre | B2: Profesores por dedicación 2019-2 a 2024-1
B4: 2019-2 | C4: 2020-1 | D4: 2020-2 | E4: 2021-1 | F4: 2021-2 | G4: 2022-1 | H4: 2022-2 | I4: 2023-1 | J4: 2023-2 | K4: 2024-1 | L4: 2024-2 | M4: 2025-1 | N4: 2025-2 | O4: 2026-1
A5: Tiempo Completo | B5: 216 | C5: 236 | D5: 231 | E5: 371 | F5: 355 | G5: 436 | H5: 503 | I5: 499 | J5: 536 | K5: 594 | L5: 591 | M5: 649 | N5: 666 | O5: 690
A6: Medio Tiempo | B6: 47 | C6: 50 | D6: 68 | E6: 118 | F6: 100 | G6: 133 | H6: 136 | I6: 183 | J6: 165 | K6: 195 | L6: 180 | M6: 273 | N6: 276 | O6: 329
A7: Hora Cátedra | B7: 1016 | C7: 948 | D7: 704 | E7: 342 | F7: 397 | G7: 303 | H7: 222 | I7: 190 | J7: 179 | K7: 199 | L7: 153 | M7: 136 | N7: 96 | O7: 63
B8: =+SUM(B5:B7) -> 1279 | C8: =+SUM(C5:C7) -> 1234 | D8: =+SUM(D5:D7) -> 1003 | E8: =+SUM(E5:E7) -> 831 | F8: =+SUM(F5:F7) -> 852 | G8: =+SUM(G5:G7) -> 872 | H8: =+SUM(H5:H7) -> 861 | I8: =+SUM(I5:I7) -> 872 | ... M8: =+SUM(M5:M7) -> 1058 | N8: =SUM(N5:N7) -> 1038 | O8: =SUM(O5:O7) -> 1082

Sheet Tabla 5
A1: Tabla NO | B1: 5
A2: Nombre | B2: Programas con condiciones iniciales aprobadas
A4: SNIES | B4: MODALIDAD | C4: SEDE | D4: FACULTAD | E4: ESCUELA | F4: PROGRAMA
A5: 54726 | B5: PRESENCIAL | C5: BOGOTÁ | D5: FIDI | E5: ESCUELA DE DISEÑO | F5: DISEÑO DE MODAS
A6: 1894 | B6: PRESENCIAL | C6: BOGOTÁ | D6: FNGS | E6: ESCUELA DE CONTADURÍA Y FINANZAS GLOBALES | F6: CONTADURÍA PÚBLICA
A7: 111178 | B7: VIRTUAL | C7: NACIONAL | D7: FSCC | E7: ESCUELA DE EDUCACIÓN E INNOVACIÓN | F7: LICENCIATURA EN EDUCACIÓN INFANTIL
A10: Nombre | B10: Programas con condiciones iniciales aprobadas 2026-1
A12: SNIES | B12: MODALIDAD | C12: SEDE | D12: FACULTAD | E12: ESCUELA | F12: PROGRAMA
A13: 101660 | B13: Virtual | C13: Nacional | D13: FSCC | E13: Escuela de Educación e Innovación | F13: Licenciatura en Ciencias Sociales
A14: 53632 | B14: Virtual | C14: Nacional | D14: FNGS | E14: Escuela de Contabilidad y Finanzas Globales | F14: Contaduría Pública
A15: 90399 | B15: Virtual | C15: Nacional | D15: FNGS | E15: Escuela de Administración y Competitividad | F15: Administracion de Empresas
A16: 102847 | B16: Presencial | C16: Medellín | D16: FNGS | E16: Escuela de Administración y Competitividad | F16: Administracion de Empresas

Sheet Tabla 6
A1: * | B1: 6
A2: Nombre | B2: Matrícula de estudiantes 2019-2 a 2024-1
B4: Nivel formación | C4: 2019-2 | D4: 2020-1 | E4: 2020-2 | F4: 2021-1 | G4: 2021-2 | H4: 2022-1 | I4: 2022-2 | J4: 2023-1 | K4: 2023-2 | L4: 2024-1 | M4: 2024-2 | N4: 2025-1 | O4: 2025-2 | P4: 2026-1
A5: Total Presencial | C5: 7501 | D5: 7426 | E5: 6292 | F5: 6113 | G5: 5601 | H5: 5505 | I5: 5239 | J5: 5614 | K5: 5627 | L5: 5800 | M5: 5585 | N5: 5979 | O5: =SUM(O6:O10) -> 6000 | P5: =SUM(P6:P10) -> 6289
A6: Presencial | B6: T profesional | C6: 31 | D6: 27 | E6: 13 | F6: 13 | G6: 6 | H6: 5 | I6: 3 | J6: 2 | K6: 2 | L6: 1 | M6: 0 | N6: 0 | O6: 0 | P6: 0
B7: Tecnológico | C7: 392 | D7: 369 | E7: 291 | F7: 275 | G7: 263 | H7: 249 | I7: 320 | J7: 385 | K7: 423 | L7: 458 | M7: 442 | N7: 435 | O7: 390 | P7: 344
B8: Universitario | C8: 6391 | D8: 6327 | E8: 5430 | F8: 5294 | G8: 4822 | H8: 4768 | I8: 4429 | J8: 4720 | K8: 4665 | L8: 4755 | M8: 4535 | N8: 4880 | O8: 5006 | P8: 5351
B9: Especialización | C9: 569 | D9: 577 | E9: 446 | F9: 438 | G9: 435 | H9: 420 | I9: 437 | J9: 470 | K9: 467 | L9: 483 | M9: 499 | N9: 538 | O9: 525 | P9: 508
B10: Maestría | C10: 118 | D10: 126 | E10: 112 | F10: 93 | G10: 75 | H10: 63 | I10: 50 | J10: 37 | K10: 70 | L10: 103 | M10: 109 | N10: 126 | O10: 79 | P10: 86
A11: Total Virtual | C11: 43613 | D11: 44262 | E11: 44718 | F11: 43590 | G11: 42676 | H11: 43415 | I11: 43449 | J11: 43568 | K11: 44083 | L11: 44161 | M11: 43840 | N11: 47762 | O11: =SUM(O12:O16) -> 48072 | P11: =SUM(P12:P16) -> 52109
A12: Virtual | B12: T profesional | C12: 312 | D12: 355 | E12: 434 | F12: 370 | G12: 383 | H12: 427 | I12: 401 | J12: 344 | K12: 353 | L12: 328 | M12: 291 | N12: 355 | O12: 346 | P12: 382
B13: Tecnológico | C13: 5405 | D13: 5544 | E13: 5448 | F13: 5371 | G13: 5106 | H13: 5025 | I13: 4869 | J13: 4702 | K13: 4550 | L13: 4401 | M13: 4079 | N13: 4311 | O13: 4233 | P13: 4475
B14: Universitario | C14: 36710 | D14: 37056 | E14: 37269 | F14: 36150 | G14: 35640 | H14: 36070 | I14: 36076 | J14: 36074 | K14: 36409 | L14: 36534 | M14: 36412 | N14: 39351 | O14: 39465 | P14: 42158
B15: Especialización | C15: 1186 | D15: 1307 | E15: 1567 | F15: 1699 | G15: 1546 | H15: 1760 | I15: 1854 | J15: 1915 | K15: 1981 | L15: 1985 | M15: 1927 | N15: 2060 | O15: 1916 | P15: 1917
B16: Maestría | G16: 1 | H16: 133 | I16: 249 | J16: 533 | K16: 790 | L16: 913 | M16: 1131 | N16: 1685 | O16: 2112 | P16: 3177
A17: Total Sede Bogotá | C17: . | D17: 51688 | E17: 51010 | F17: 49703 | G17: 48277 | H17: 48920 | I17: 48688 | J17: 49182 | K17: 49710 | L17: 49961 | M17: 49425 | N17: 53741 | O17: =+O11+O5 -> 54072 | P17: =+P11+P5 -> 58398

Sheet Gráfico 2
A1: Gráfico No | B1: 2
A2: Nombre | B2: Profesores por nivel de formación
B4: 2019-2 | C4: 2020-1 | D4: 2020-2 | E4: 2021-1 | F4: 2021-2 | G4: 2022-1 | H4: 2022-2 | I4: 2023-1 | J4: 2023-2 | K4: 2024-1 | L4: 2024-2 | M4: 2025-1 | N4: 2025-2 | O4: 2026-1
A5: Doctorado | B5: 35 | C5: 41 | D5: 37 | E5: 47 | F5: 37 | G5: 51 | H5: 47 | I5: 46 | J5: 53 | K5: 71 | L5: 77 | M5: 94 | N5: 89 | O5: 85
A6: Maestría | B6: 784 | C6: 830 | D6: 691 | E6: 604 | F6: 666 | G6: 593 | H6: 597 | I6: 686 | J6: 699 | K6: 766 | L6: 708 | M6: 819 | N6: 794 | O6: 829
A7: Especialización | B7: 286 | C7: 233 | D7: 190 | E7: 122 | F7: 104 | G7: 188 | H7: 170 | I7: 95 | J7: 81 | K7: 91 | L7: 85 | M7: 83 | N7: 97 | O7: 98
A8: Pregrado | B8: 174 | C8: 130 | D8: 85 | E8: 58 | F8: 45 | G8: 40 | H8: 47 | I8: 45 | J8: 47 | K8: 60 | L8: 54 | M8: 62 | N8: 58 | O8: 70
B9: =+SUM(B5:B8) -> 1279 | C9: =+SUM(C5:C8) -> 1234 | D9: =+SUM(D5:D8) -> 1003 | E9: =+SUM(E5:E8) -> 831 | F9: =+SUM(F5:F8) -> 852 | G9: =+SUM(G5:G8) -> 872 | H9: =+SUM(H5:H8) -> 861 | I9: =+SUM(I5:I8) -> 872 | ... O9: =+SUM(O5:O8) -> 1082

Sheet Tabla 7
A1: Tabla NO | B1: 7
A2: Nombre | B2: Graduados por nivel de formación y modalidad 2019-2 a 2024-1
A4: Modalidad | B4: Nivel de formación | C4: 2019-2 | D4: 2020-1 | E4: 2020-2 | F4: 2021-1 | G4: 2021-2 | H4: 2022-1 | I4: 2022-2 | J4: 2023-1 | K4: 2023-2 | L4: 2024-1 | M4: 2024-2 | N4: 2025-1 | O4: 2025-2 | P4: 2026-1
A5: Virtual | B5: Técnico Profesional | C5: 28 | D5: 31 | E5: 32 | F5: 50 | G5: 48 | H5: 33 | I5: 57 | J5: 57 | K5: 45 | L5: 22 | M5: 74 | N5: 26
B6: Tecnológico | C6: 423 | D6: 493 | E6: 398 | F6: 507 | G6: 564 | H6: 531 | I6: 554 | J6: 418 | K6: 523 | L6: 361 | M6: 649 | N6: 378
B7: Universitario | C7: 2626 | D7: 3704 | E7: 4102 | F7: 5449 | G7: 5127 | H7: 5646 | I7: 4973 | J7: 4845 | K7: 4923 | L7: 3858 | M7: 4783 | N7: 3564
B8: Especialización | C8: 556 | D8: 348 | E8: 725 | F8: 527 | G8: 1088 | H8: 250 | I8: 1033 | J8: 501 | K8: 1122 | L8: 682 | M8: 1262 | N8: 1209
B9: Maestría | K9: 1 | L9: 10 | M9: 35 | N9: 56
B10: Virtual | C10: 3633 | D10: 4576 | E10: 5257 | F10: 6533 | G10: 6827 | H10: 6460 | I10: 6617 | J10: 5821 | K10: 6614 | L10: 4933 | M10: 6803 | N10: 5233
A11: Presencial | B11: Técnico Profesional | C11: 5 | D11: 1 | E11: 9 | F11: 6 | G11: 5 | H11: 3 | I11: 1 | J11: 2 | K11: 2 | M11: 2
B12: Tecnológico | C12: 96 | D12: 68 | E12: 92 | F12: 113 | G12: 75 | H12: 66 | I12: 78 | J12: 74 | K12: 81 | L12: 43 | M12: 67 | N12: 68
B13: Universitario | C13: 749 | D13: 853 | E13: 1136 | F13: 1101 | G13: 1062 | H13: 1041 | I13: 881 | J13: 849 | K13: 795 | L13: 735 | M13: 799 | N13: 746
B14: Especialización | C14: 257 | D14: 282 | E14: 341 | F14: 265 | G14: 298 | H14: 190 | I14: 146 | J14: 192 | K14: 295 | L14: 214 | M14: 297 | N14: 219
B15: Maestría | C15: 14 | D15: 10 | E15: 16 | F15: 18 | G15: 31 | H15: 18 | I15: 24 | J15: 7 | K15: 14 | L15: 117 | M15: 163 | N15: 266
B16: Presencial | C16: 1121 | D16: 1214 | E16: 1594 | F16: 1503 | G16: 1471 | H16: 1318 | I16: 1130 | J16: 1124 | K16: 1187 | L16: 1109 | M16: 1328 | N16: 1299
A17: Total | C17: 4754 | D17: 5790 | E17: 6851 | F17: 8036 | G17: 8298 | H17: 7778 | I17: 7747 | J17: 6945 | K17: 7801 | L17: 6042 | M17: 8131 | N17: 6532

Sheet Tabla 8
A1: Tabla NO | B1: 8
A2: Nombre | B2: Grupos de investigación categorizados en Ministerio de Ciencias, Tecnología e Innovación Minciencias
A4: Facultad | B4: Grupo | C4: Categoría
A5: Facultad de Ingeniería, Diseño e Innovación | B5: CITIC | C5: A
B6: Diseño, Artefacto y Sociedad – DAS | C6: C
B7: Optimización, Infraestructura y Automatización – OPINA | C7: B
B8: E-TIC | C8: REC
A9: Facultad de Sociedad, Cultura y Creatividad | B9: Derecho, Sociedad y Empresa – DSE | C9: A
B10: MERCADEO I+2 - MI2 | C10: A
B11: Psicología Educación y Cultura – PEC | C11: A1
B12: Educación, Innovación y Sociedad – EIS | C12: B
B13: Narrativas, Creación y Estéticas – NCE | C13: C
B14: Ciudadanías, Acción social y Desarrollo – CIADE | C14: C
B15: Comunicación Estratégica y Creativa – CEC | C15: C
B16: Grupo de Investigación en Gestión de las Organizaciones Laborales y Seguridad Laboral | C16: C
A17: Facultad Negocios, Gestión y Sostenibilidad | B17: Economía, Negocios y Desarrollo Internacional – ENDI | C17: A
B18: Administración, Competitividad y Sostenibilidad – GACS | C18: B
B19: Equipo de Investigación en Contabilidad, Organizaciones y Sociedad – EICOS | C19: B
B20: GIAP | C20: B
B21: Nota: Cnvocatoria 957 Minciencias

Sheet Tabla 9
A1: Tabla NO | B1: 9
A2: Nombre | B2: Investigadores categorizados Minciencias. Convocatoria 957
B4: Investigadores
A5: Junior | B5: 80
A6: Asociado | B6: 32
A7: Senior | B7: 10
A8: Total | B8: =SUM(B5:B7) -> 122
A9: Resultados concocatoria 957 Minciencas

Sheet Tabla 10
A1: Tabla NO | B1: 10
A2: Nombre | B2: Semilleros por facultad 2019-2- a 2026-1
B4: Facultad | C4: 2019 | D4: 2020 | E4: 2021 | F4: 2022 | G4: 2023 | H4: 2024 | I4: 2025 | J4: 2026-1
B5: Facultad Ingeniería Diseño e Innovación | C5: 23 | D5: 26 | E5: 24 | F5: 36 | G5: 33 | H5: 31 | I5: 30 | J5: 31
B6: Facultad Negocios, Gestión y Sostenibilidad | C6: 32 | D6: 36 | E6: 44 | F6: 34 | G6: 32 | H6: 30 | I6: 27 | J6: 28
B7: Facultad Sociedad, Cultura y Creatividad | C7: 54 | D7: 63 | E7: 65 | F7: 54 | G7: 68 | H7: 71 | I7: 58 | J7: 63
B8: Total | C8: 109 | D8: 125 | E8: 133 | F8: 124 | G8: 133 | H8: 132 | I8: 115 | J8: =SUM(J5:J7) -> 122

Sheet Tabla 23
A1: * | B1: 23
A2: Nombre | B2: Resultados de las acciones de formación integral
A4: Dimensión | B4: Acciones | C4: 2019 | D4: 2020 | E4: 2021 | F4: 2022 | G4: 2023 | H4: 2024 | I4: 2025 | J4: 2026-1
A5: Académica | B5: Semilleros de investigación | C5: 109 | D5: 125 | E5: 133 | F5: 124 | G5: 133 | H5: 132 | I5: 115 | K5: tabla 10
B6: Clases espejo | C6: 13 | D6: 86 | E6: 108 | F6: 106 | G6: 68 | H6: 97 | I6: 101 | K6: tabla 145
B7: Estudiantes | C7: 103 | D7: 2059 | E7: 4269 | F7: 2893 | G7: 1401 | H7: 3747 | I7: 2493 | K7: tabla 145
B8: Uso de los ambientes inmersivos por los estudiantes | C8: - | D8: - | E8: 85 | F8: 4389 | G8: 4284 | H8: 3593 | I8: 14410 | K8: Tabla 47
B9: Promedio global Pruebas Saber Pro | C9: 145 | D9: 147 | E9: 142 | F9: 143 | G9: 141 | H9: 141 | I9: 141 | K9: revisar tabla 131
A10: Socioemocional | B10: Estudiantes en centro de Psicología | C10: 558 | D10: 180 | E10: 183 | F10: 216 | G10: 114 | H10: 299 | I10: 198 | K10: revisar tabla 131
B11: Participación de estudiantes en actividades de Cultura inclusiva y Prácticas pedagógicas | C11: 65 | D11: 2578 | E11: 4121 | F11: 245 | G11: 1628 | H11: 151 | I11: 301 | K11: tabla 209 y tabla 131 a 134
A12: Cultural y artística | B12: Estudiantes en actividades deportivas | C12: 2246 | D12: 1177 | E12: 1526 | F12: 1975 | G12: 2561 | H12: 2947 | I12: 2501 | J12: 1939 | K12: Tabla 166
B13: Estudiantes en actividades culturales y artísticas | C13: 957 | D13: 633 | E13: 414 | F13: 755 | G13: 1103 | H13: 1149 | I13: 1010 | J13: 12686 | K13: Tabla 165
A14: Ambiental y sostenible | B14: Artículos Divulgación periódica revistas: Especializada en los Objetivos de Desarrollo Sostenible - ODS | C14: - | D14: - | E14: 11 | F14: 10 | G14: - | H14: - | I14: - | K14: Tabla 44

Sheet Tabla 29
A1: Tabla NO | B1: 29
A2: Nombre | B2: Visualizaciones del informe de sostenibilidad anual
A4: AÑO DEL INFORME | B4: 2025-1 | C4: 2025-2 | D4: 2026-1
A5: 2019 | B5: 3292 | C5: 3664 | D5: 4274
A6: 2020 | B6: 2320 | C6: 2512 | D6: 3958
A7: 2021 | B7: 3637 | C7: 3908 | D7: 6344
A8: 2022 | B8: 162767 | C8: 175069 | D8: 233123
A9: 2023 | B9: 8709 | C9: 8854 | D9: 9786
A10: 2024 | B10: 18195 | C10: 33111 | D10: 89295
A11: 2025 | D11: 41816

Sheet Tabla 32
A1: Tabla NO | B1: 32
A2: Nombre | B2: Personal administrativo beneficiado con políticas de estímulos
B4: 2019-2 | C4: 2020-1 | D4: 2020-2 | E4: 2021-1 | F4: 2021-2 | G4: 2022-1 | H4: 2022-2 | I4: 2023-1 | J4: 2023-2 | K4: 2024-1 | L4: 2024-2 | M4: 2025-1 | N4: 2025-2 | O4: 2026-1
A5: Auxilios otorgados para formaciones como bilingüismo, capacitaciones | B5: 13 | C5: 8 | D5: 8 | E5: 5 | F5: 7 | G5: 40 | H5: 34 | I5: 36 | J5: 24 | K5: 27 | L5: 21 | M5: 15
A6: Número de becas para colaboradores y familiares (administrativos) | B6: 96 | C6: 92 | D6: 82 | E6: 111 | F6: 120 | G6: 78 | H6: 92 | I6: 93 | J6: 109 | K6: 85 | L6: =38+26 -> 64 | M6: =82+38 -> 120

Sheet Tabla 33
A1: Tabla NO | B1: 33
A2: Nombre | B2: Participación de administrativos en formación
A4: Año | B4: 2019-2 | C4: 2020-1 | D4: 2020-2 | E4: 2021-1 | F4: 2021-2 | G4: 2022-1 | H4: 2022-2 | I4: 2023-1 | J4: 2023-2 | K4: 2024-1 | L4: 2024-2 | M4: 2025-1 | N4: 2025-2 | O4: 2026-1 | P4: Total general
A5: Bilingüe | D5: 19 | E5: 6 | F5: 2 | G5: 26 | H5: 20 | I5: 32 | J5: 21 | K5: 22 | L5: 16 | M5: 13 | P5: =+SUM(B5:O5) -> 177
A6: Complementaria | B6: 185 | C6: 238 | D6: 1038 | E6: 80 | F6: 721 | G6: 630 | H6: 1519 | I6: 129 | J6: 1994 | K6: 1329 | L6: 1804 | M6: 226 | P6: =+SUM(B6:O6) -> 9893
A7: Digital | B7: 2 | C7: 102 | D7: 427 | E7: 409 | F7: 677 | G7: 15 | H7: 384 | I7: 267 | J7: 406 | K7: 475 | L7: 240 | M7: 100 | P7: =+SUM(B7:O7) -> 3504
A8: Disciplinar | B8: 13 | C8: 61 | D8: 175 | E8: 2752 | F8: 842 | G8: 1025 | H8: 593 | I8: 471 | J8: 375 | K8: 1177 | L8: 2633 | M8: 673 | P8: =+SUM(B8:O8) -> 10790
A9: Investigación, Innovación, Internacionalización | B9: 21 | C9: 86 | D9: 62 | E9: 25 | F9: 92 | G9: 56 | H9: 25 | I9: 44 | J9: 43 | K9: 12 | L9: 19 | M9: 56 | P9: =+SUM(B9:O9) -> 541
A10: Pedagógica | B10: 20 | C10: 98 | D10: 74 | E10: 220 | F10: 142 | G10: 47 | H10: 39 | I10: 18 | J10: 37 | K10: 102 | L10: 48 | M10: 737 | P10: =+SUM(B10:O10) -> 1582
A11: POLISIGS | B11: 37 | C11: 856 | D11: 1938 | E11: 1138 | F11: 2158 | G11: 489 | H11: 555 | I11: 708 | J11: 220 | K11: 928 | L11: 2201 | M11: 322 | P11: =+SUM(B11:O11) -> 11550
A12: Total general | B12: 278 | C12: 1441 | D12: 3733 | E12: 4630 | F12: 4634 | G12: 2288 | H12: 3135 | I12: 1669 | J12: 3096 | K12: =SUM(K5:K11) -> 4045 | L12: =SUM(L5:L11) -> 6961 | M12: =SUM(M5:M11) -> 2127 | P12: =+SUM(B12:O12) -> 38037

Sheet Tabla 34
A1: Tabla NO | B1: 34
A2: Nombre | B2: Ascensos en la planta administrativa
A4: Año | B4: Número
A5: 2019 | B5: 27
A6: 2020 | B6: 38
A7: 2021 | B7: 40
A8: 2022 | B8: 50
A9: 2023 | B9: 42
A10: 2024 | B10: 28
A11: 2025 | B11: 23 | C11: Se actualiza al cierre de año
A12: 2026-1 | B12: 9
A13: Total | B13: =SUM(B5:B12) -> 257
A14: Total general | B14: =+B13 -> 257

Sheet Ilustración 20
A1: Tabla NO | B1: Ilustración 20
A2: Nombre | B2: Frecuencia de uso de medios de comunicación para informarse
A4: Medio / Plataforma | B4: Instagram | G4: Buscadores (Google, Bing, Safari, Otros) | L4: Youtube | Q4: Facebook | V4: Servicios Streaming | AA4: Televisión por suscripción/plataformas on demand | AF4: Otras Redes Sociales | AK4: Twitter | AP4: Web de medios informativos | AU4: Spotify | AZ4: Televisión Nacional | BE4: TikTok | BJ4: Prensa, revistas y publicaciones digitales | BO4: Radio | BT4: Prensa, revistas y publicaciones impresas
A5: Año | B5: 2022 | C5: 2023 | D5: 2024 | E5: 2025 | F5: 2026 | G5: 2022 | H5: 2023 | I5: 2024 | J5: 2025 | K5: 2026 | L5: 2022 | M5: 2023 | N5: 2024 | O5: 2025 | P5: 2026 | Q5: 2022 | R5: 2023 | S5: 2024 | T5: 2025 | U5: 2026 | V5: 2022 | W5: 2023 | X5: 2024 | Y5: 2025 | Z5: 2026 | AA5: 2022 | AB5: 2023 | AC5: 2024 | AD5: 2025 | AE5: 2026 | AF5: 2022 | AG5: 2023 | AH5: 2024 | AI5: 2025 | AJ5: 2026 | AK5: 2022 | AL5: 2023 | AM5: 2024 | AN5: 2025 | AO5: 2026 | AP5: 2022 | AQ5: 2023 | AR5: 2024 | AS5: 2025 | AT5: 2026 | AU5: 2022 | AV5: 2023 | AW5: 2024 | AX5: 2025 | AY5: 2026 | AZ5: 2022 | BA5: 2023 | BB5: 2024 | BC5: 2025 | BD5: 2026 | BE5: 2022 | BF5: 2023 | BG5: 2024 | BH5: 2025 | BI5: 2026 | BJ5: 2022 | BK5: 2023 | BL5: 2024 | BM5: 2025 | BN5: 2026 | BO5: 2022 | BP5: 2023 | BQ5: 2024 | BR5: 2025 | BS5: 2026 | BT5: 2022 | BU5: 2023 | BV5: 2024 | BW5: 2025 | BX5: 2026
A6: Lo uso todo el tiempo | B6: 54 | C6: 48 | D6: 43 | E6: 33 | F6: 45 | G6: - | H6: 45 | I6: 55 | J6: 38 | K6: 50 | L6: 46 | M6: 46 | N6: 43 | O6: 33 | P6: 40 | Q6: 49 | R6: 44 | S6: 47 | T6: 36 | U6: 38 | V6: 32 | W6: 30 | X6: 31 | Y6: 30 | Z6: 26 | AA6: 29 | AB6: 25 | AC6: 21 | AD6: 24 | AE6: 16 | AF6: 29 | AG6: 23 | AH6: 38 | AI6: 32 | AJ6: 36 | AK6: 32 | AL6: 28 | AM6: 16 | AN6: 13 | AO6: 9 | AP6: 27 | AQ6: 22 | AR6: 17 | AS6: 16 | AT6: 12 | AU6: - | AV6: 26 | AW6: 22 | AX6: 22 | AY6: 25 | AZ6: 26 | BA6: 23 | BB6: 25 | BC6: 23 | BD6: 14 | BE6: 35 | BF6: 32 | BG6: 36 | BH6: 33 | BI6: 38 | BJ6: 21 | BK6: 15 | BL6: 17 | BM6: 16 | BN6: 12 | BO6: 16 | BP6: 14 | BQ6: 13 | BR6: 14 | BS6: 8 | BT6: 9 | BU6: 9 | BV6: 7 | BW6: 9 | BX6: 6
A7: Lo uso de forma frecuente | B7: 29 | C7: 34 | D7: 26 | E7: 33 | F7: 28 | G7: - | H7: 36 | I7: 30 | J7: 34 | K7: 34 | L7: 36 | M7: 34 | N7: 35 | O7: 39 | P7: 32 | Q7: 34 | R7: 34 | S7: 29 | T7: 41 | U7: 31 | V7: 35 | W7: 39 | X7: 35 | Y7: 35 | Z7: 34 | AA7: 33 | AB7: 33 | AC7: 34 | AD7: 33 | AE7: 27 | AF7: 37 | AG7: 34 | AH7: 33 | AI7: 33 | AJ7: 34 | AK7: 28 | AL7: 29 | AM7: 16 | AN7: 21 | AO7: 13 | AP7: 38 | AQ7: 35 | AR7: 27 | AS7: 27 | AT7: 25 | AU7: - | AV7: 30 | AW7: 24 | AX7: 27 | AY7: 23 | AZ7: 34 | BA7: 32 | BB7: 29 | BC7: 28 | BD7: 29 | BE7: 23 | BF7: 24 | BG7: 27 | BH7: 34 | BI7: 26 | BJ7: 36 | BK7: 35 | BL7: 27 | BM7: 27 | BN7: 25 | BO7: 27 | BP7: 28 | BQ7: 21 | BR7: 25 | BS7: 17 | BT7: 22 | BU7: 21 | BV7: 18 | BW7: 21 | BX7: 13
A8: Lo uso ocasionalmente | B8: 8 | C8: 11 | D8: 21 | E8: 23 | F8: 16 | G8: - | H8: 15 | I8: 11 | J8: 17 | K8: 10 | L8: 13 | M8: 15 | N8: 17 | O8: 20 | P8: 23 | Q8: 10 | R8: 12 | S8: 17 | T8: 15 | U8: 16 | V8: 19 | W8: 20 | X8: 23 | Y8: 23 | Z8: 29 | AA8: 21 | AB8: 24 | AC8: 25 | AD8: 24 | AE8: 28 | AF8: 23 | AG8: 31 | AH8: 19 | AI8: 25 | AJ8: 20 | AK8: 17 | AL8: 19 | AM8: 26 | AN8: 23 | AO8: 21 | AP8: 25 | AQ8: 30 | AR8: 32 | AS8: 30 | AT8: 28 | AU8: - | AV8: 18 | AW8: 20 | AX8: 24 | AY8: 21 | AZ8: 25 | BA8: 30 | BB8: 27 | BC8: 26 | BD8: 26 | BE8: 15 | BF8: 17 | BG8: 15 | BH8: 16 | BI8: 16 | BJ8: 27 | BK8: 31 | BL8: 32 | BM8: 30 | BN8: 28 | BO8: 29 | BP8: 28 | BQ8: 32 | BR8: 25 | BS8: 32 | BT8: 36 | BU8: 31 | BV8: 38 | BW8: 31 | BX8: 32
A9: Casi nunca / nunca lo uso | B9: 9 | C9: 7 | D9: 11 | E9: 11 | F9: 12 | G9: - | H9: 4 | I9: 4 | J9: 11 | K9: 6 | L9: 5 | M9: 5 | N9: 5 | O9: 8 | P9: 5 | Q9: 7 | R9: 10 | S9: 7 | T9: 9 | U9: 15 | V9: 14 | W9: 11 | X9: 11 | Y9: 13 | Z9: 11 | AA9: 17 | AB9: 18 | AC9: 20 | AD9: 20 | AE9: 30 | AF9: 11 | AG9: 12 | AH9: 10 | AI9: 10 | AJ9: 10 | AK9: 23 | AL9: 24 | AM9: 42 | AN9: 43 | AO9: 57 | AP9: 10 | AQ9: 13 | AR9: 23 | AS9: 28 | AT9: 36 | AU9: - | AV9: 26 | AW9: 34 | AX9: 27 | AY9: 31 | AZ9: 15 | BA9: 15 | BB9: 19 | BC9: 24 | BD9: 32 | BE9: 27 | BF9: 27 | BG9: 22 | BH9: 17 | BI9: 20 | BJ9: 16 | BK9: 19 | BL9: 24 | BM9: 28 | BN9: 36 | BO9: 28 | BP9: 30 | BQ9: 34 | BR9: 36 | BS9: 43 | BT9: 33 | BU9: 39 | BV9: 37 | BW9: 39 | BX9: 48

Sheet Ilustración 21
A1: Tabla NO | B1: Ilustración 21
A2: Nombre | B2: Medios destacados para el Poli
A5: Canal | B5: Promedio de categoría 2022 | C5: Promedio de categoría 2023 | D5: Promedio de categoría 2024 | E5: Promedio de categoría 2025 | F5: Promedio de categoría 2026 | G5: Poli 2022 | H5: Poli 2023 | I5: Poli 2024 | J5: Poli 2025 | K5: Poli 2026
A6: TBCA | B6: 0 | C6: 0 | D6: 98 | E6: 98 | F6: 99 | G6: 76 | H6: 71 | I6: 91 | J6: 94 | K6: 93
A7: Internet/Redes sociales | B7: 25 | C7: 25 | D7: 88 | E7: 88 | F7: 90 | G7: 31 | H7: 29 | I7: 46 | J7: 48 | K7: 57
A8: TV | B8: 19 | C8: 19 | D8: 64 | E8: 65 | F8: 58 | G8: 27 | H8: 25 | I8: 25 | J8: 25 | K8: 24
A9: Eventos, actividades y ferias universitarias | B9: 15 | C9: 16 | D9: 57 | E9: 57 | F9: 52 | G9: 16 | H9: 18 | I9: 19 | J9: 15 | K9: 19
A10: Recomendación de un amigo o familiar | B10: 16 | C10: 14 | D10: 74 | E10: 74 | F10: 72 | G10: 14 | H10: 15 | I10: 26 | J10: 23 | K10: 28
A11: Radio | B11: 13 | C11: 14 | D11: 57 | E11: 57 | F11: 48 | G11: 17 | H11: 16 | I11: 20 | J11: 17 | K11: 17
A12: Campus, sedes, centros de servicios, oficinas | B12: 12 | C12: 13 | D12: 57 | E12: 57 | F12: 50 | G12: 13 | H12: 15 | I12: 20 | J12: 11 | K12: 17
A13: Vallas y paraderos | B13: 11 | C13: 11 | D13: 53 | E13: 54 | F13: 53 | G13: 11 | H13: 14 | I13: 17 | J13: 17 | K13: 17
A14: Periódicos / Revistas | B14: 12 | C14: 10 | D14: 51 | E14: 51 | F14: 41 | G14: 12 | H14: 12 | I14: 14 | J14: 13 | K14: 12
A15: En algún otro lugar | B15: 7 | C15: 9 | D15: 34 | E15: 34 | F15: 39 | G15: 8 | H15: 11 | I15: 8 | J15: 9 | K15: 9
A16: Transporte público | B16: 7 | C16: 8 | D16: 45 | E16: 46 | F16: 42 | G16: 9 | H16: 8 | I16: 13 | J16: 14 | K16: 12
A17: Anuncios por internet | B17: 20 | C17: 0 | D17: 0 | E17: 0 | F17: 0 | G17: 22 | H17: 0 | I17: 0 | J17: 0 | K17: 0
A18: No he visto/oído | B18: 0 | C18: 0 | D18: 2 | E18: 2 | F18: 1 | G18: 24 | H18: 29 | I18: 9 | J18: 6 | K18: 7

Sheet Ilustración 22
A1: Tabla NO | B1: Ilustración 22
A2: Nombre | B2: Alcance de personas en Redes sociales cuentas del Poli
A4: Periodo | B4: Valor
A5: 2019-2 | B5: 13200188
A6: 2020-1 | B6: 34020199
A7: 2020-2 | B7: 17009280
A8: 2021-1 | B8: 19029200
A9: 2021-2 | B9: 27009290
A10: 2022-1 | B10: 46554692
A11: 2022-2 | B11: 31564416
A12: 2023-1 | B12: 50097397
A13: 2023-2 | B13: 80857419
A14: 2024-1 | B14: 33220565
A15: 2024-2 | B15: 39978224
A16: 2025-1 | B16: 91672969
... A18: 2026-1 | B18: 21399531

Sheet Tabla 36
A1: Tabla NO | B1: 36
A2: Nombre | B2: Leads obtenidos año a año por canal en el Poli
A4: Canales | B4: 2019 | C4: 2020 | D4: 2021 | E4: 2022 | F4: 2023 | G4: 2024.1 | H4: 2024-2 | I4: 2025-1 | J4: 2025-2 | K4: 2026-1
A5: ATL | B5: 18.233 | C5: 14.324 | D5: 17.807 | E5: 20.995 | F5: 30.827 | G5: 13291 | H5: 11793 | I5: 14538 | J5: 14259 | K5: 9186
A6: B2B | B6: 9.393 | C6: 2.009 | D6: 3.609 | E6: 9.323 | F6: 21.653 | G6: 20582 | H6: 15974 | I6: 19968 | J6: 26920 | K6: 28597
A7: BTL | B7: 4.622 | C7: 476 | D7: 1.198 | E7: 19.619 | F7: 7.481 | G7: 5461 | H7: 5753 | I7: 5200 | J7: 3539 | K7: 361
A8: CSU | B8: 37.114 | C8: 35.572 | D8: 21.573 | E8: 20.026 | F8: 38.695 | G8: 18245 | H8: 24362 | I8: 17930 | J8: 14519 | K8: 14285
A9: DIGITAL | B9: 136.96 | C9: 169.926 | D9: 175.394 | E9: 157.391 | F9: 184.4 | G9: 120682 | H9: 104251 | I9: 105415 | J9: 87620 | K9: 101831
A10: HIGH SCHOOL | B10: 3.345 | C10: 31 | D10: 232 | E10: 627 | F10: 2.258 | G10: 3868 | H10: 709 | I10: 3465 | J10: =2139+6 -> 2145 | K10: 2695
A11: INBOUND | B11: 30.211 | C11: 10.203 | D11: 4.823 | E11: 4.673 | F11: 2.984 | G11: 934 | H11: 753 | I11: 2099 | J11: 1843 | K11: 1426
A12: REMARKETING | B12: 1.807 | C12: 1.306 | D12: 1.191 | E12: 1.227 | F12: 533 | G12: 117 | H12: 77 | I12: 197 | J12: 318 | K12: 34
A13: WHATSAPP | I13: 1137 | J13: 1280 | K13: 5882
A14: TOTAL | B14: 241.685 | C14: 233.847 | D14: 225.827 | E14: 233.881 | F14: 288.831 | G14: 183180 | H14: 163672 | I14: =+SUM(I5:I13) -> 169949 | J14: =+SUM(J5:J13) -> 152443 | K14: =+SUM(K5:K13) -> 164297

Sheet Tabla 39
A1: Tabla NO | B1: 39
A2: Nombre | B2: Tipología de recursos documentales en la Biblioteca
B5: 2025 | D5: 2026-1
A6: Tipología Documental | B6: Títulos | C6: Volúmenes | D6: Títulos | E6: Volúmenes
A7: Libros Físicos | B7: 24.233 | C7: 46.172 | D7: 24.234 | E7: 46260
A8: Publicaciones seriadas impresas | B8: 284 | C8: 284 | D8: 310 | E8: 310
A9: Material Audiovisual (películas educativas, cine, documentales y contenido en streaming) | B9: 5.298 | C9: 5.298 | D9: 5.298 | E9: 5.298
A10: Libros digitales | B10: 140.278 | C10: 140.278 | D10: 145.665 | E10: 145665
A11: Recursos electrónicos Bibliográficos (revistas, artículos, noticias, legislación y publicaciones académicas, monografías, tesis) | B11: 18,000,000 | C11: 18,000,000 | D11: 18,000,000 | E11: 18,000,000
A12: Repositorio Institucional | B12: 4.831 | C12: 4.831 | D12: 5.506 | E12: 5.506

Sheet Tabla 40
A1: Tabla NO | B1: 40
A2: Nombre | B2: Libros por área de conocimiento
B3: 2025 | D3: 2026
A4: Áreas del conocimiento | B4: Títulos | C4: Volúmenes | D4: Títulos | E4: Volúmenes
A5: ARTES | B5: 1823 | C5: 5342 | D5: 1844 | E5: 5366
A6: CIENCIAS ADMINISTRATIVAS (CIENCIAS APLICADAS) | B6: 5443 | C6: 10846 | D6: 5516 | E6: 10957
A7: CIENCIAS NATURALES Y MATEMATICAS | B7: 4646 | C7: 7176 | D7: 4665 | E7: 7210
A8: CIENCIAS SOCIALES | B8: 5527 | C8: 10139 | D8: 5592 | E8: 10239
A9: FILOSOFIA Y PSICOLOGIA | B9: 1878 | C9: 2316 | D9: 1919 | E9: 2385
A10: GEOGRAFIA E HISTORIA | B10: 806 | C10: 1237 | D10: 811 | E10: 1244
A11: LENGUAS | B11: 615 | C11: 1302 | D11: 616 | E11: 1304
A12: LITERATURA | B12: 1984 | C12: 3427 | D12: 2025 | E12: 3509
A13: METODOLOGIA, SISTEMAS, INFORMACION Y PERIODISMO | B13: 1123 | C13: 3791 | D13: 1164 | E13: 3847
A14: RELIGION | B14: 81 | C14: 111 | D14: 81 | E14: 111
A15: TOTAL | B15: =SUM(B5:B14) -> 23926 | C15: =SUM(C5:C14) -> 45687 | D15: =SUM(D5:D14) -> 24233 | E15: 46172

Sheet Tabla 41
A1: Tabla NO | B1: 41
A2: Nombre | B2: Revistas por área de conocimiento
A4: Revistas por Áreas | B4: 2025 | C4: 2026-1
A5: Revistas de Ciencias Administrativas, Económicas y Contables | B5: 33 | C5: 37
A6: Revistas de Ciencias Sociales | B6: 21 | C6: 25
A7: Revistas de Ingeniería y Ciencias Básicas | B7: 48 | C7: 48
A8: Revistas de Mercadeo, Comunicación y Artes | B8: 11 | C8: 20
A9: Revistas Generales | B9: 164 | C9: 171
A10: Periódicos y códigos Legis | B10: 7 | C10: 9
A11: Total | B11: 284 | C11: =SUM(C5:C10) -> 310

Sheet Tabla 42
A1: Tabla NO | B1: 42
A2: Nombre | B2: Recursos bibliográficos 2019-2 a 2026-1
B4: 2019 | C4: 2020 | D4: 2020-2 | E4: 2021-1 | F4: 2021 | G4: 2022 | H4: 2022 | I4: 2023 | J4: 2023- | K4: 2024-1 | L4: 2024-2 | M4: 2025-1 | N4: 2025-2 | O4: 2026-1
B5: -2 | C5: -1 | F5: -2 | G5: -1 | H5: -2 | I5: -1 | J5: 2
A6: NUMERO BIBLIOTECAS | B6: 3 | C6: 3 | D6: 3 | E6: 3 | F6: 3 | G6: 3 | H6: 3 | I6: 3 | J6: 3 | K6: 3 | L6: 3 | M6: 3 | N6: 3 | O6: 3
A7: NUMERO DE BASES DE DATOS ESPECIALIZADAS | B7: 93 | C7: 190 | D7: 290 | E7: 390 | F7: 491 | G7: 599 | H7: 707 | I7: 814 | J7: 921 | K7: 111 | L7: 111 | M7: 114 | N7: 114 | O7: 114
A8: NUMERO DE LIBROS ELECTRONICOS | B8: 90278 | C8: 91000 | D8: 91000 | E8: 91000 | F8: 115780 | G8: 120845 | H8: 122642 | I8: 136642 | J8: 137103 | K8: 143000 | L8: 143000 | M8: 143000 | N8: 145665 | O8: 145665
A9: TITULOS DE LIBROS PROPIOS | B9: 23775 | C9: 23814 | D9: 23853 | E9: 23853 | F9: 23854 | G9: 23914 | H9: 24368 | I9: 24270 | J9: 24738 | K9: 21688 | L9: 23914 | M9: 23926 | N9: 24233 | O9: 24274
A10: VOLUMENES (LIBROS) DE LA COLECCION TOTAL PROPIOS | B10: 46083 | C10: 46122 | D10: 46161 | E10: 46161 | F10: 46167 | G10: 46259 | H10: 46905 | I10: 46838 | J10: 47539 | K10: 41695 | L10: 45653 | M10: 45687 | N10: 46172 | O10: 46260
A11: NUMERO DE TITULOS DE LIBROS ADQUIRIDOS EN EL PERIODO ACADEMICO | B11: 239 | C11: 39 | D11: 39 | E11: - | F11: 1 | G11: 53 | H11: 454 | I11: 1 | J11: 468 | K11: 36 | L11: 580 | M11: 12 | N11: 307 | O11: 41
A12: NUMERO DE VOLUMENES (LIBROS) DE LA COLECCION TOTAL ADQUIRIDOS EN EL PERIODO ACADEMICO | B12: 324 | C12: 39 | D12: 39 | E12: - | F12: 6 | G12: 70 | H12: 646 | I12: 14 | J12: 701 | K12: 13 | L12: 664 | M12: 34 | N12: 485 | O12: 45
A13: NUMERO DE TITULOS DE PUBLICACIONES PERIODICAS | B13: 171 | C13: 171 | D13: 171 | E13: 171 | F13: 171 | G13: 51 | H13: 51 | I13: 51 | J13: 51 | K13: 289 | L13: 289 | M13: 289 | N13: 310 | O13: 310
